Workbook

Sheet Bìa
A1: Tên system | K1: Loại system | W1: TKCB | AP1: Người tạo | AT1: Ngày tạo | AY1: Người update | BC1: Ngày update | BH1: Version
A2: Manager User | K2: Thiết kế API | AP2: ThanhPD | AT2: 44930 | AY2: =LOOKUP(2,1/('Lịch sử thay đổi'!H:H<>""),'Lịch sử thay đổi'!H:H) -> ThanhPD | BC2: =LOOKUP(2,1/('Lịch sử thay đổi'!B:B<>""),'Lịch sử thay đổi'!B:B) -> 44930 | BH2: =LOOKUP(2,1/('Lịch sử thay đổi'!O:O<>""),'Lịch sử thay đổi'!O:O) -> 0.1
A4: Category chức năng | U4: Hạng mục | Z4: Delete employee | AP4: Bìa
L16: Manager User
L24: =K2&"/"&H4&"/"&Z4 -> Thiết kế API//Delete employee
Q44: Ngày phê chuẩn | AA44: Người phê chuẩn | AQ44: Version

Sheet Lịch sử thay đổi
A1: Tên system | K1: Loại system | W1: =IF(Bìa!W1="","",Bìa!W1) -> TKCB | AP1: Người tạo | AT1: Ngày tạo | AY1: Người update | BC1: Ngày update | BH1: Version
A2: =IF(Bìa!A2="","",Bìa!A2) -> Manager User | K2: =IF(Bìa!K2="","",Bìa!K2) -> Thiết kế API | AP2: =IF(Bìa!AP2="","",Bìa!AP2) -> ThanhPD | AT2: =IF(Bìa!AT2="","",Bìa!AT2) -> 44930 | AY2: =IF(Bìa!AY2="","",Bìa!AY2) -> ThanhPD | BC2: =IF(Bìa!BC2="","",Bìa!BC2) -> 44930 | BH2: =IF(Bìa!BH2="","",Bìa!BH2) -> 0.1
A4: Category chức năng | H4: =IF(Bìa!H4="","",Bìa!H4) | U4: Hạng mục | Z4: =IF(Bìa!Z4="","",Bìa!Z4) -> Delete employee | AP4: Lịch sử thay đổi
B8: ■Lịch sử thay đổi
B10: Date | H10: Người update | O10: Version | S10: Nội dung thay đổi | AX10: Ngày phê chuẩn | BD10: Người phê chuẩn
B11: 44930 | H11: ThanhPD | O11: 0.1 | S11: Tạo mới tài liệu

Sheet Khái quát
A1: Tên system | K1: Loại system | W1: =IF(Bìa!W1="","",Bìa!W1) -> TKCB | AP1: Người tạo | AT1: Ngày tạo | AY1: Người update | BC1: Ngày update | BH1: Version
A2: =IF(Bìa!A2="","",Bìa!A2) -> Manager User | K2: =IF(Bìa!K2="","",Bìa!K2) -> Thiết kế API | AP2: =IF(Bìa!AP2="","",Bìa!AP2) -> ThanhPD | AT2: =IF(Bìa!AT2="","",Bìa!AT2) -> 44930 | AY2: =IF(Bìa!AY2="","",Bìa!AY2) -> ThanhPD | BC2: =IF(Bìa!BC2="","",Bìa!BC2) -> 44930 | BH2: =IF(Bìa!BH2="","",Bìa!BH2) -> 0.1
A4: Category chức năng | U4: Hạng mục | Z4: =IF(Bìa!Z4="","",Bìa!Z4) -> Delete employee | AP4: Khái quát
B8: 1. Khái quát
C9: Lấy thông tin chi tiết nhân viên
B11: 2. Request
C12: Request URL
C13: No. | E13: Service | W13: API name | AI13: Method HTTP | AQ13: Note
C14: 1 | E14: employee | W14: =Z4 -> Delete employee | AI14: DELETE
C16: Request Parameter
C17: No. | E17: Parameter | L17: Bắt buộc | S17: Kiểu | Z17: Giá trị default | AG17: Tên hạng mục | AQ17: Note
C18: 1 | E18: employeeId | L18: o | S18: number | Z18: {} | AG18: id của employee cần xóa
C20: ※Sample
D21: /employee/1
B25: 3. Response
C26: Trường hợp api trả về response bình thường
C28: No. | E28: json key name | N28: Kiểu | S28: Tên hạng mục | AC28: Note
C29: 1 | E29: code | N29: number
C30: =ROW()-ROW($C$28) -> 2 | E30: employeeId | N30: number
C31: =ROW()-ROW($C$28) -> 3 | E31: message | N31: object
C33: ※Sample
D34: {
D35: "code": "200"
D36: "employeeId": "1",
D37: "message": {
E38: "code": "MSG003"
E39: "params": []
E40: }
D41: }
C46: Trường hợp api trả về lỗi
C48: ※Sample
D49: {
D50: "code": "500"
D51: "employeeId": "1",
D52: "message": {
E53: "code": "ER015"
E54: "params": []
E55: }
D56: }

Sheet Flow xử lý
A1: Tên system | K1: Loại system | W1: =IF(Bìa!W1="","",Bìa!W1) -> TKCB | AP1: Người tạo | AT1: Ngày tạo | AY1: Người update | BC1: Ngày update | BH1: Version
A2: =IF(Bìa!A2="","",Bìa!A2) -> Manager User | K2: =IF(Bìa!K2="","",Bìa!K2) -> Thiết kế API | AP2: =IF(Bìa!AP2="","",Bìa!AP2) -> ThanhPD | AT2: =IF(Bìa!AT2="","",Bìa!AT2) -> 44930 | AY2: =IF(Bìa!AY2="","",Bìa!AY2) -> ThanhPD | BC2: =IF(Bìa!BC2="","",Bìa!BC2) -> 44930 | BH2: =IF(Bìa!BH2="","",Bìa!BH2) -> 0.1
A4: Category chức năng | H4: =IF(Bìa!H4="","",Bìa!H4) | U4: Hạng mục | Z4: =IF(Bìa!Z4="","",Bìa!Z4) -> Delete employee | AP4: Flow xử lý

Sheet Chi tiết xử lý
A1: Tên system | K1: Loại system | W1: =IF(Bìa!W1="","",Bìa!W1) -> TKCB | AP1: Người tạo | AT1: Ngày tạo | AY1: Người update | BC1: Ngày update | BH1: Version
A2: =IF(Bìa!A2="","",Bìa!A2) -> Manager User | K2: =IF(Bìa!K2="","",Bìa!K2) -> Thiết kế API | AP2: =IF(Bìa!AP2="","",Bìa!AP2) -> ThanhPD | AT2: =IF(Bìa!AT2="","",Bìa!AT2) -> 44930 | AY2: =IF(Bìa!AY2="","",Bìa!AY2) -> ThanhPD | BC2: =IF(Bìa!BC2="","",Bìa!BC2) -> 44930 | BH2: =IF(Bìa!BH2="","",Bìa!BH2) -> 0.1
A4: Category chức năng | H4: =IF(Bìa!H4="","",Bìa!H4) | U4: Hạng mục | Z4: =IF(Bìa!Z4="","",Bìa!Z4) -> Delete employee | AP4: Chi tiết xử lý
B7: Xử lý common:
C8: <Không có>
B9: Xử lý chi tiết:
C10: 1. Validate prameter
E11: 1.1 Validate parameter [employeeId]
F12: Nếu ko tồn tại parameter này thì trả về lỗi có mã code ER001, tham số "ＩＤ"
F13: Nếu không tồn tại trong bảng employees.employee_id thì trả về lỗi có mã code ER014, tham số "ＩＤ"
E14: Nếu có lỗi thì chuyển sang bước [4. Tạo dữ liệu response cho API]
B15: Khởi tạo transaction
C16: 2. Xóa thông tin trình độ tiếng Nhật của nhân viên
D17: ■Danh sách bảng sử dụng
F19: No | H19: Tên bảng logic | X19: ID bảng vật lý | AN19: Create | AQ19: Refer | AT19: Update | AW19: Xóa
F20: 1 | H20: Thông tin chứng chỉ tiếng Nhật của nhân viên | X20: employees_certifications | AW20: 〇
D23: ■Table access
E24: ① | F24: Điều kiện xóa
E25: No | G25: Tên bảng | Q25: Tên hạng mục | AA25: Giá trị
E26: 1 | G26: employees_certifications | Q26: employee_id | AA26: = employee_id từ parameter [employeeId]
E28: Nếu có lỗi khi xóa thì trả về lỗi và chuyển sang bước [4. Tạo dữ liệu response cho API]
C29: 3. Xóa thông tin nhân viên
E30: ■Danh sách bảng sử dụng
G32: No | I32: Tên bảng logic | Y32: ID bảng vật lý | AO32: Create | AR32: Refer | AU32: Update | AX32: Xóa
G33: 1 | I33: Thông tin nhân viên | Y33: employees | AX33: 〇
D36: ■Table access
E37: ① | F37: Điều kiện xóa
E38: No | G38: Tên bảng | Q38: Tên hạng mục | AA38: Giá trị
E39: 1 | G39: employees | Q39: employee_id | AA39: = employee_id từ parameter [employeeId]
B41: Nếu không có lỗi gì xảy ra thì Commit transaction
B42: Nếu có lỗi xảy ra thì Rollback transaction
E43: Nếu có lỗi khi xóa thì trả về lỗi với mã lỗi ER015 và chuyển sang bước [4. Tạo dữ liệu response cho API]
C45: 4. Tạo dữ liệu response cho API
D46: - Trường hợp không có lỗi xảy ra:
D47: No. | F47: Key | O47: Giá trị | AD47: Note
D48: 1 | F48: code | O48: 200
D49: 2 | F49: employeeId | O49: Lấy giá trị từ parameter [employeeId]
D50: 3 | F50: message | O50: {code: "MSG003", params: []}
D52: - Trường hợp có lỗi xảy ra
D53: No. | F53: Key | O53: Giá trị | AD53: Note
...

Sheet Tham chiếu
A1: Tên system | K1: Loại system | W1: =IF(Bìa!W1="","",Bìa!W1) -> TKCB | AP1: Người tạo | AT1: Ngày tạo | AY1: Người update | BC1: Ngày update | BH1: Version
A2: =IF(Bìa!A2="","",Bìa!A2) -> Manager User | K2: =IF(Bìa!K2="","",Bìa!K2) -> Thiết kế API | AP2: =IF(Bìa!AP2="","",Bìa!AP2) -> ThanhPD | AT2: =IF(Bìa!AT2="","",Bìa!AT2) -> 44930 | AY2: =IF(Bìa!AY2="","",Bìa!AY2) -> ThanhPD | BC2: =IF(Bìa!BC2="","",Bìa!BC2) -> 44930 | BH2: =IF(Bìa!BH2="","",Bìa!BH2) -> 0.1
A4: Category chức năng | H4: =IF(Bìa!H4="","",Bìa!H4) | U4: Hạng mục | Z4: =IF(Bìa!Z4="","",Bìa!Z4) -> Delete employee | AP4: Tham chiếu
C7: Danh sách tài liệu tham chiếu
D9: No. | F9: Mã tham chiếu | L9: Tài liệu tham chiếu
